Workbook

Sheet Resumen
A3: (vacío) | C3: GAS
A4: CONDENSADORA | B4: NOMBRE | C4: (vacío) | D4: R-410A | E4: R-32 | F4: R-407 | G4: Total Resultado
A5: A | B5: Informática
B6: Jose Maria
B7: Jurídico
B8: Office 4a planta
B9: Pasillo
B10: Secretaria direción
B11: Sr Jaume
B12: Toni font
B13: Vestidor
B14: Sala Reuniones IT
B15: Ruben Masip
A16: AA | B16: Sala Reuniones DUM
B17: Pasillo DUM
B18: Roger AMK1
B19: AMK2
B20: Despacho 2 DUM
B21: Pool DUM
B22: Gerencia DUM
B23: Office DUM
A24: B | B24: Polivalente 1
B25: Despatx Oriol
B26: Despatx Mimi
B27: Despatx Iñaki
B28: Conchi
B29: Tania
B30: Despatx Gemma Peris
B31: Sala Intermedia CLUB/DUM
B32: Entrada Club
B33: Pasillo Markant
A34: C | B34: Auditores
B35: Ana Rion
B36: Juana
B37: Jaume Font sostre
B38: Elena
B39: Esther
B40: Biblioteca 1
B41: Anna fossas
B42: Biblioteca 2
...

Sheet Cassette
A1: NUM_CASSETTE | B1: NUM_SECUENCIA | C1: ESTADO | D1: PLANTA | E1: NOMBRE | F1: POTENCIA_CALOR | G1: POTENCIA_FRIO | H1: MARCA/MODELO | I1: NUM_SERIE_CAS | J1: CONDENSADORA | K1: LOCALIZACIÓN_CONDENSADORA | L1: GAS | M1: FECHA_INSTALACION | N1: FECHA_BAJA | O1: FECHA_REVISION | P1: AVERIA | Q1: FOTO | R1: OBSERVACIONES
A2: 14 | B2: 1 | C2: ACTIVA | D2: 1 Planta | E2: Albert Sala | J2: F | K2: =IFERROR(VLOOKUP(J2,Condensadoras!A:H,7,0),"") -> Azotea - Detrás | L2: =IFERROR(VLOOKUP(J2,Condensadoras!A:H,8,0),"") -> R-410A | M2: 01/01/2007 | O2: 29/12/2026
A3: 18 | B3: 1 | C3: ACTIVA | D3: 1 Planta | E3: Office 1a planta | J3: F | K3: =IFERROR(VLOOKUP(J3,Condensadoras!A:H,7,0),"") -> Azotea - Detrás | L3: =IFERROR(VLOOKUP(J3,Condensadoras!A:H,8,0),"") -> R-410A | M3: 01/01/2007 | O3: 28/12/2026
A4: 19 | B4: 1 | C4: ACTIVA | D4: 1 Planta | E4: Agustin Turiel | J4: F | K4: =IFERROR(VLOOKUP(J4,Condensadoras!A:H,7,0),"") -> Azotea - Detrás | L4: =IFERROR(VLOOKUP(J4,Condensadoras!A:H,8,0),"") -> R-410A | M4: 01/01/2007 | O4: 28/12/2026
A5: 21 | B5: 1 | C5: ACTIVA | D5: 1 Planta | E5: Cande | J5: F | K5: =IFERROR(VLOOKUP(J5,Condensadoras!A:H,7,0),"") -> Azotea - Detrás | L5: =IFERROR(VLOOKUP(J5,Condensadoras!A:H,8,0),"") -> R-410A | M5: 01/01/2007 | O5: 28/12/2026
A6: 9 | B6: 1 | C6: ACTIVA | D6: 1 Planta | E6: Ferran | J6: G | K6: =IFERROR(VLOOKUP(J6,Condensadoras!A:H,7,0),"") -> Azotea - Detrás | L6: =IFERROR(VLOOKUP(J6,Condensadoras!A:H,8,0),"") -> R-410A | M6: 01/01/2007 | O6: 28/12/2026
A7: 10 | B7: 1 | C7: ACTIVA | D7: 1 Planta | E7: José Moreno | J7: G | K7: =IFERROR(VLOOKUP(J7,Condensadoras!A:H,7,0),"") -> Azotea - Detrás | L7: =IFERROR(VLOOKUP(J7,Condensadoras!A:H,8,0),"") -> R-410A | M7: 01/01/2007 | O7: 27/12/2026
A8: 11 | B8: 1 | C8: ACTIVA | D8: 1 Planta | E8: Julio | J8: G | K8: =IFERROR(VLOOKUP(J8,Condensadoras!A:H,7,0),"") -> Azotea - Detrás | L8: =IFERROR(VLOOKUP(J8,Condensadoras!A:H,8,0),"") -> R-410A | M8: 01/01/2007 | O8: 27/12/2026
A9: 11 | B9: 1 | C9: ACTIVA | D9: 1 Planta | E9: Laura Serra | J9: G | K9: =IFERROR(VLOOKUP(J9,Condensadoras!A:H,7,0),"") -> Azotea - Detrás | L9: =IFERROR(VLOOKUP(J9,Condensadoras!A:H,8,0),"") -> R-410A | M9: 39083
A10: 12 | B10: 1 | C10: ACTIVA | D10: 1 Planta | E10: Josep Martinez | J10: G | K10: =IFERROR(VLOOKUP(J10,Condensadoras!A:H,7,0),"") -> Azotea - Detrás | L10: =IFERROR(VLOOKUP(J10,Condensadoras!A:H,8,0),"") -> R-410A | M10: 01/01/2007 | O10: 27/12/2026
A11: 13 | B11: 1 | C11: ACTIVA | D11: 1 Planta | E11: Jose Roldán | J11: G | K11: =IFERROR(VLOOKUP(J11,Condensadoras!A:H,7,0),"") -> Azotea - Detrás | L11: =IFERROR(VLOOKUP(J11,Condensadoras!A:H,8,0),"") -> R-410A | M11: 01/01/2007 | O11: 30/12/2026
A12: 14 | B12: 1 | C12: ACTIVA | D12: 1 Planta | E12: Ana Pastor | J12: G | K12: =IFERROR(VLOOKUP(J12,Condensadoras!A:H,7,0),"") -> Azotea - Detrás | L12: =IFERROR(VLOOKUP(J12,Condensadoras!A:H,8,0),"") -> R-410A | M12: 39083
A13: 15 | B13: 1 | C13: ACTIVA | D13: 1 Planta | E13: Begoña | J13: G | K13: =IFERROR(VLOOKUP(J13,Condensadoras!A:H,7,0),"") -> Azotea - Detrás | L13: =IFERROR(VLOOKUP(J13,Condensadoras!A:H,8,0),"") -> R-410A | M13: 01/01/2007 | O13: 27/12/2026
A14: 16 | B14: 1 | C14: ACTIVA | D14: 1 Planta | E14: Carlos Alegre | J14: G | K14: =IFERROR(VLOOKUP(J14,Condensadoras!A:H,7,0),"") -> Azotea - Detrás | L14: =IFERROR(VLOOKUP(J14,Condensadoras!A:H,8,0),"") -> R-410A | M14: 01/01/2007 | O14: 27/12/2026
A15: 17 | B15: 1 | C15: ACTIVA | D15: 1 Planta | E15: Agustin Turiel | J15: G | K15: =IFERROR(VLOOKUP(J15,Condensadoras!A:H,7,0),"") -> Azotea - Detrás | L15: =IFERROR(VLOOKUP(J15,Condensadoras!A:H,8,0),"") -> R-410A | O15: 28/12/2026
A16: F15 | B16: 1 | C16: ACTIVA | D16: 1 Planta | E16: Adrian Gil | J16: V | K16: =IFERROR(VLOOKUP(J16,Condensadoras!A:H,7,0),"") -> Patio Olivera | L16: =IFERROR(VLOOKUP(J16,Condensadoras!A:H,8,0),"") -> R-410A
A17: 40 | B17: 1 | C17: ACTIVA | D17: 1 Planta | E17: Anna Pastor | J17: W | K17: =IFERROR(VLOOKUP(J17,Condensadoras!A:H,7,0),"") -> Patio Olivera | L17: =IFERROR(VLOOKUP(J17,Condensadoras!A:H,8,0),"") -> R-32 | O17: 28/12/2026
A18: F10 | B18: 1 | C18: ACTIVA | D18: 1 Planta | E18: Yolanda Romo | J18: X | K18: =IFERROR(VLOOKUP(J18,Condensadoras!A:H,7,0),"") -> Azotea-Detrás | L18: =IFERROR(VLOOKUP(J18,Condensadoras!A:H,8,0),"") -> R-410A
A19: 45 | B19: 1 | C19: ACTIVA | D19: 1 Planta | E19: Ortigosa | F19: 37,5 kw | G19: 33,5 kw | H19: PUMY-P300YBM2 | J19: Z | K19: =IFERROR(VLOOKUP(J19,Condensadoras!A:H,7,0),"") -> Azotea - Detrás | L19: =IFERROR(VLOOKUP(J19,Condensadoras!A:H,8,0),"") -> R-410A
A20: 46 | B20: 1 | C20: ACTIVA | D20: 1 Planta | E20: Sala Comercial | F20: 37,5 kw | G20: 33,5 kw | H20: PUMY-P300YBM2 | J20: Z | K20: =IFERROR(VLOOKUP(J20,Condensadoras!A:H,7,0),"") -> Azotea - Detrás | L20: =IFERROR(VLOOKUP(J20,Condensadoras!A:H,8,0),"") -> R-410A
A21: 47 | B21: 1 | C21: ACTIVA | D21: 1 Planta | E21: Avellaneda | F21: 37,5 kw | G21: 33,5 kw | H21: PUMY-P300YBM2 | J21: Z | K21: =IFERROR(VLOOKUP(J21,Condensadoras!A:H,7,0),"") -> Azotea - Detrás | L21: =IFERROR(VLOOKUP(J21,Condensadoras!A:H,8,0),"") -> R-410A
A22: 48 | B22: 1 | C22: ACTIVA | D22: 1 Planta | E22: Lado Gestor Socio | F22: 37,5 kw | G22: 33,5 kw | H22: PUMY-P300YBM2 | J22: Z | K22: =IFERROR(VLOOKUP(J22,Condensadoras!A:H,7,0),"") -> Azotea - Detrás | L22: =IFERROR(VLOOKUP(J22,Condensadoras!A:H,8,0),"") -> R-410A
A23: 49 | B23: 1 | C23: ACTIVA | D23: 1 Planta | E23: Luis Martinez | F23: 37,5 kw | G23: 33,5 kw | H23: PUMY-P300YBM2 | J23: Z | K23: =IFERROR(VLOOKUP(J23,Condensadoras!A:H,7,0),"") -> Azotea - Detrás | L23: =IFERROR(VLOOKUP(J23,Condensadoras!A:H,8,0),"") -> R-410A | M23: 01/01/2012 | O23: 28/12/2026
A24: 32 | B24: 1 | C24: ACTIVA | D24: 2 Planta | E24: Auditores | J24: C | K24: =IFERROR(VLOOKUP(J24,Condensadoras!A:H,7,0),"") -> Azotea - Detrás | L24: =IFERROR(VLOOKUP(J24,Condensadoras!A:H,8,0),"") -> R-410A | M24: 01/01/2012 | O24: 28/12/2026
A25: 33 | B25: 1 | C25: ACTIVA | D25: 2 Planta | E25: Ana Rion | J25: C | K25: =IFERROR(VLOOKUP(J25,Condensadoras!A:H,7,0),"") -> Azotea - Detrás | L25: =IFERROR(VLOOKUP(J25,Condensadoras!A:H,8,0),"") -> R-410A | M25: 01/01/2012 | O25: 29/12/2026
A26: 34 | B26: 1 | C26: ACTIVA | D26: 2 Planta | E26: Santi | J26: C | K26: =IFERROR(VLOOKUP(J26,Condensadoras!A:H,7,0),"") -> Azotea - Detrás | L26: =IFERROR(VLOOKUP(J26,Condensadoras!A:H,8,0),"") -> R-410A | M26: 01/01/2012 | O26: 29/12/2026
A27: 35 | B27: 1 | C27: ACTIVA | D27: 2 Planta | E27: Roser | J27: C | K27: =IFERROR(VLOOKUP(J27,Condensadoras!A:H,7,0),"") -> Azotea - Detrás | L27: =IFERROR(VLOOKUP(J27,Condensadoras!A:H,8,0),"") -> R-410A | M27: 01/01/2012 | O27: 28/12/2026
A28: 36 | B28: 1 | C28: ACTIVA | D28: 2 Planta | E28: Juana | J28: C | K28: =IFERROR(VLOOKUP(J28,Condensadoras!A:H,7,0),"") -> Azotea - Detrás | L28: =IFERROR(VLOOKUP(J28,Condensadoras!A:H,8,0),"") -> R-410A | M28: 01/01/2012 | O28: 28/12/2026
A29: 37 | B29: 1 | C29: ACTIVA | D29: 2 Planta | E29: Jaume Font sostre | J29: C | K29: =IFERROR(VLOOKUP(J29,Condensadoras!A:H,7,0),"") -> Azotea - Detrás | L29: =IFERROR(VLOOKUP(J29,Condensadoras!A:H,8,0),"") -> R-410A | M29: 01/01/2012 | O29: 28/12/2026
A30: 38 | B30: 1 | C30: ACTIVA | D30: 2 Planta | E30: Elena | J30: C | K30: =IFERROR(VLOOKUP(J30,Condensadoras!A:H,7,0),"") -> Azotea - Detrás | L30: =IFERROR(VLOOKUP(J30,Condensadoras!A:H,8,0),"") -> R-410A | M30: 01/01/2012 | O30: 28/12/2026
A31: 39 | B31: 1 | C31: ACTIVA | D31: 2 Planta | E31: Esther | J31: C | K31: =IFERROR(VLOOKUP(J31,Condensadoras!A:H,7,0),"") -> Azotea - Detrás | L31: =IFERROR(VLOOKUP(J31,Condensadoras!A:H,8,0),"") -> R-410A | M31: 01/01/2012 | O31: 28/12/2026
A32: 40 | B32: 1 | C32: ACTIVA | D32: 2 Planta | E32: Biblioteca 1 | J32: C | K32: =IFERROR(VLOOKUP(J32,Condensadoras!A:H,7,0),"") -> Azotea - Detrás | L32: =IFERROR(VLOOKUP(J32,Condensadoras!A:H,8,0),"") -> R-410A | M32: 40909
A33: 41 | B33: 1 | C33: ACTIVA | D33: 2 Planta | E33: Anna fossas | J33: C | K33: =IFERROR(VLOOKUP(J33,Condensadoras!A:H,7,0),"") -> Azotea - Detrás | L33: =IFERROR(VLOOKUP(J33,Condensadoras!A:H,8,0),"") -> R-410A | M33: 01/01/2012 | O33: 28/12/2026
A34: 42 | B34: 1 | C34: ACTIVA | D34: 2 Planta | E34: Biblioteca 2 | J34: C | K34: =IFERROR(VLOOKUP(J34,Condensadoras!A:H,7,0),"") -> Azotea - Detrás | L34: =IFERROR(VLOOKUP(J34,Condensadoras!A:H,8,0),"") -> R-410A | M34: 01/01/2012 | O34: 28/12/2026
A35: 43 | B35: 1 | C35: ACTIVA | D35: 2 Planta | E35: Archivo 43 | J35: C | K35: =IFERROR(VLOOKUP(J35,Condensadoras!A:H,7,0),"") -> Azotea - Detrás | L35: =IFERROR(VLOOKUP(J35,Condensadoras!A:H,8,0),"") -> R-410A | M35: 01/01/2012 | O35: 28/12/2026
A36: F12 | B36: 1 | C36: ACTIVA | D36: 2 Planta | E36: Mitad PC | J36: S | K36: =IFERROR(VLOOKUP(J36,Condensadoras!A:H,7,0),"") -> Azotea - Frente | L36: =IFERROR(VLOOKUP(J36,Condensadoras!A:H,8,0),"") -> R-410A | M36: 01/01/2012 | O36: 28/12/2026
A37: F13 | B37: 1 | C37: ACTIVA | D37: 2 Planta | E37: Roser | J37: T | K37: =IFERROR(VLOOKUP(J37,Condensadoras!A:H,7,0),"") -> Azotea - Frente | L37: =IFERROR(VLOOKUP(J37,Condensadoras!A:H,8,0),"") -> R-410A | M37: 01/01/2012 | O37: 28/12/2026
A38: F14 | B38: 1 | C38: ACTIVA | D38: 2 Planta | E38: Recibidor Anna Fossas | J38: U | K38: =IFERROR(VLOOKUP(J38,Condensadoras!A:H,7,0),"") -> Azotea - Frente | L38: =IFERROR(VLOOKUP(J38,Condensadoras!A:H,8,0),"") -> R-410A | M38: 01/01/2012 | O38: 28/12/2026
A39: F11 | B39: 1 | C39: ACTIVA | D39: 2 Planta | E39: Esther Quintela | J39: X | K39: =IFERROR(VLOOKUP(J39,Condensadoras!A:H,7,0),"") -> Azotea-Detrás | L39: =IFERROR(VLOOKUP(J39,Condensadoras!A:H,8,0),"") -> R-410A | M39: 01/01/2012 | O39: 28/12/2026
A40: F9 | B40: 1 | C40: ACTIVA | D40: 2 Planta | E40: Jaume Font Pared | J40: X | K40: =IFERROR(VLOOKUP(J40,Condensadoras!A:H,7,0),"") -> Azotea-Detrás | L40: =IFERROR(VLOOKUP(J40,Condensadoras!A:H,8,0),"") -> R-410A | M40: 01/01/2012 | O40: 28/12/2026
...

Sheet Condensadoras
A1: CONDENSADORA | B1: NUM_SECUENCIA | C1: ESTADO | D1: MARCA | E1: MODEL | F1: NUM_SERIE_COND | G1: LOCALIZACIÓN_CONDENSADORA | H1: GAS | I1: FECHA_INSTALACION | J1: FECHA_BAJA | K1: FECHA_REVISION | L1: AVERIA | M1: OBSERVACIONES
A2: A | B2: 1 | C2: ACTIVA | D2: MITSUBISHI | F2: 0 | G2: Azotea - Detrás | H2: R-410A | I2: 01/01/2007 | K2: 27/12/2026 | M2: Posible fecha sin verificar
A3: AA | B3: 1 | C3: ACTIVA | D3: MITSUBISHI | E3: PURY-P300YNW-A | G3: Azotea-Otra Porteria | H3: R-410A | I3: 17/06/2025 | K3: 17/06/2026
A4: B | B4: 1 | C4: ACTIVA | D4: MITSUBISHI | G4: Azotea - Detrás | H4: R-410A | I4: 01/01/2012 | K4: 28/12/2026 | M4: Posible fecha sin verificar
A5: C | B5: 1 | C5: ACTIVA | D5: MITSUBISHI | G5: Azotea - Detrás | H5: R-410A | I5: 01/01/2012 | K5: 28/12/2026 | M5: Posible fecha sin verificar
A6: CON1 | B6: 1 | C6: ACTIVA | D6: MITSUBISHI | E6: SUZ-SM71VA | G6: Azotea - Detrás | H6: R-32 | I6: 01/01/2007 | K6: 27/12/2026 | M6: Posible fecha sin verificar
A7: CON2 | B7: 1 | C7: ACTIVA | D7: MITSUBISHI | E7: SUZ-SM71VA | G7: Azotea - Detrás | H7: R-32 | I7: 01/01/2007 | K7: 27/12/2026 | M7: Posible fecha sin verificar
A8: D | B8: 1 | C8: ACTIVA | D8: MITSUBISHI | G8: Azotea - Detrás | H8: R-407 | J8: 42004 | M8: DESINSTALADO 2024
A9: E | B9: 1 | C9: ACTIVA | D9: MITSUBISHI | G9: Azotea - Detrás | H9: R-407 | I9: 01/01/2012 | K9: 28/12/2026 | M9: Posible fecha sin verificar
A10: F | B10: 1 | C10: ACTIVA | D10: MITSUBISHI | G10: Azotea - Detrás | H10: R-410A | I10: 01/01/2012 | K10: 28/12/2026 | M10: Posible fecha sin verificar
A11: G | B11: 1 | C11: ACTIVA | D11: MITSUBISHI | G11: Azotea - Detrás | H11: R-410A | I11: 01/01/2012 | K11: 28/12/2026 | M11: Posible fecha sin verificar
A12: I | B12: 1 | C12: ACTIVA | D12: MITSUBISHI | E12: SUZ-KA50VA | G12: Azotea - Detrás | H12: R-410A | I12: 01/01/2012 | K12: 28/12/2026 | M12: Posible fecha sin verificar
A13: J | B13: 1 | C13: ACTIVA | D13: MITSUBISHI | E13: SUZ-KA50VA | G13: Azotea - Frente | H13: R-410A | I13: 01/01/2012 | K13: 28/12/2026 | M13: Posible fecha sin verificar
A14: JA1 | B14: 1 | C14: ACTIVA | D14: MITSUBISHI | G14: Azotea-Detrás | H14: R-22 | J14: 42004 | M14: DESINSTALADO 2024
A15: K | B15: 1 | C15: ACTIVA | D15: MITSUBISHI | G15: Azotea - Frente | H15: R-22 | J15: 42004 | M15: DESINSTALADO 2024
A16: L | B16: 1 | C16: ACTIVA | D16: MITSUBISHI | E16: PUHZ-RP140YKA | G16: Azotea - Frente | H16: R-410A | I16: 01/01/2006 | K16: 27/12/2026 | M16: Posible fecha sin verificar
A17: M | B17: 1 | C17: ACTIVA | D17: MITSUBISHI | E17: PUHZ-RP140YKA | G17: Azotea - Frente | H17: R-410A | I17: 01/01/2006 | K17: 27/12/2026 | M17: Posible fecha sin verificar
A18: N | B18: 1 | C18: ACTIVA | D18: MITSUBISHI | E18: PUHZ-RP140YKA | G18: Azotea - Frente | H18: R-410A | I18: 01/01/2006 | K18: 27/12/2026 | M18: Posible fecha sin verificar
A19: O | B19: 1 | C19: ACTIVA | D19: MITSUBISHI | E19: SUZ-M50VA | G19: Azotea - Frente | H19: R-32 | I19: 01/01/2020 | K19: 30/12/2026 | M19: Posible fecha sin verificar
A20: P | B20: 1 | C20: ACTIVA | D20: MITSUBISHI | E20: SUZ-M35VA | G20: Azotea - Frente | H20: R-32 | I20: 01/01/2015 | K20: 29/12/2026 | M20: Posible fecha sin verificar
A21: PB2 | B21: 1 | C21: ACTIVA | D21: MITSUBISHI | G21: Azotea-Detrás | H21: R-22 | J21: 42004 | M21: Linea Amarilla
A22: PB3 | B22: 1 | C22: ACTIVA | D22: MITSUBISHI | G22: Azotea-Detrás | H22: R-22 | J22: 42004 | M22: Linea Roja
A23: PB4 | B23: 1 | C23: ACTIVA | D23: MITSUBISHI | E23: SUZ-SM71VA | G23: Patio Olivera | H23: R-410A | I23: 01/07/2024 | K23: 01/07/2026
A24: Q | B24: 1 | C24: ACTIVA | D24: MITSUBISHI | E24: SUZ-M35VA | G24: Azotea - Frente | H24: R-32 | I24: 01/01/2015 | K24: 29/12/2026 | M24: Posible fecha sin verificar
A25: R | B25: 1 | C25: ACTIVA | D25: MITSUBISHI | G25: Azotea-Detrás | H25: R-22 | J25: 42004
A26: S | B26: 1 | C26: ACTIVA | D26: MITSUBISHI | E26: SUZ-KA60VA2 | G26: Azotea - Frente | H26: R-410A | I26: 01/01/2015 | K26: 29/12/2026 | M26: Posible fecha sin verificar
A27: T | B27: 1 | C27: ACTIVA | D27: MITSUBISHI | E27: SUZ-KA60VA2 | G27: Azotea - Frente | H27: R-410A | I27: 01/01/2015 | K27: 29/12/2026 | M27: Posible fecha sin verificar
A28: U | B28: 1 | C28: ACTIVA | D28: MITSUBISHI | E28: SUZ-KA50VA | G28: Azotea - Frente | H28: R-410A | I28: 01/01/2015 | K28: 29/12/2026 | M28: Posible fecha sin verificar
A29: V | B29: 1 | C29: ACTIVA | D29: MITSUBISHI | E29: KA35VA6 | G29: Patio Olivera | H29: R-410A | I29: 01/01/2015 | K29: 29/12/2026 | M29: Posible fecha sin verificar
A30: W | B30: 1 | C30: ACTIVA | D30: MITSUBISHI | E30: SUZ-M35VA | G30: Patio Olivera | H30: R-32 | I30: 01/01/2015 | K30: 29/12/2026 | M30: Posible fecha sin verificar
A31: X | B31: 1 | C31: ACTIVA | D31: MITSUBISHI | E31: PUMY-P300YBM2 | G31: Azotea-Detrás | H31: R-410A | I31: 02/08/2024 | K31: 02/08/2026
A32: Y | B32: 1 | C32: ACTIVA | D32: MITSUBISHI | E32: PUMY-P300YBM | G32: Azotea - Detrás | H32: R-410A | I32: 01/01/2015 | K32: 29/12/2026 | M32: Posible fecha sin verificar
A33: Z | B33: 1 | C33: ACTIVA | D33: MITSUBISHI | E33: PUMY-P300YBM | G33: Azotea - Detrás | H33: R-410A | I33: 17/06/2025 | K33: 17/06/2026

Sheet Gases
D2: Según Mitsubishi | H2: Según Toshiba | K2: Toshiba diu:
C3: PCG/PCA | D3: Venta | E3: Mantenimiento | H3: Venta | I3: Mantenimiento | K3: 1. Fabricació d´equips VRF amb R410A fins 1/gener/2029
B4: Anteriores | G4: Anteriores | K4: 2. Fabricació d´equips VRF amb R32 fins 1/gener/2033
B5: R-22 | G5: R-22 | K5: 3. Disponibilitat de R410A i R32 per manteniments. Disponible fins 2050 amb una reducció de la quota d´importació molt important fins el 2030 i després paulatina. Hi haurà un increment de disponibilitat de R410A com a gas regenerat (no verge).
B6: R-407 | C6: 1774 | D6: ???? | E6: ???? | G6: R-407 | H6: ???? | I6: ????
B7: R-410A | C7: 2088 | D7: 2025 | E7: mínimo 2030 | G7: R-410A | H7: 2029 | I7: 2050 ???
B8: R-32 | C8: 675 | D8: sustituye R410A | E8: mínimo 2030 | G8: R-32 | H8: 2033 | I8: 2050 ???

Sheet AVERIAS
A1: NUM_AVERIA | B1: ACCION_DE_REPARADA | C1: EQUIPO_AVERIADO | D1: CODIGO | E1: ESTADO | F1: PLANTA | G1: LOCALIZACION | H1: FECHA_AVERIA | I1: MAIL_ENVIADO | J1: OBSERVACIONES

Sheet PARAM_GASES
A1: GAS | B1: PCG/PCA | C1: FECHA CADUCIDAD | D1: FECHA REVISION | E1: OBSERVACIONES
A2: R-22
A3: R-32 | B3: 675 | E3: sustituye R410A
A4: R-407 | B4: 1774
A5: R-410A | B5: 2088

Sheet PARAM_MARCAS
A1: MARCA | B1: DESCRIPCION
A2: MITSUBISHI

Sheet PARAM_MODELOS_CAS
A1: MODELO | B1: DESCRIPCION
A2: PUMY-P300YBM2
A3: PURY-P300YNWa2

Sheet PARAM_MODELOS_COND
A1: MODELO | B1: DESCRIPCION
A2: KA35VA6
A3: PUHZ-RP140YKA
A4: PUMY-P300YBM
A5: PUMY-P300YBM2
A6: PURY-P300YNW-A
A7: SUZ-KA50VA
A8: SUZ-KA60VA2
A9: SUZ-M35VA
A10: SUZ-M50VA
A11: SUZ-SM71VA

Sheet PARAM_PLANTAS
A1: PLANTA | B1: DESCRIPCION
A2: 1 Planta
A3: 2 Planta
A4: 3 Planta
A5: 4 Planta
A6: Planta Baja

Sheet PARAM_LOC_COND
A1: LOCALIZACION_CONDENSADORA
A2: Azotea - Detrás
A3: Azotea - Frente
A4: Azotea-Detrás
A5: Azotea-Otra Porteria
A6: Patio Olivera

Sheet PARAM_UBICACIONES_CASSETTES
A1: NOMBRE
A2: Adrian Gil
A3: Agustin Turiel
A4: Albert Sala
A5: AMK2
A6: Ana Pastor
A7: Ana Rion
A8: Anna fossas
A9: Anna Pastor
A10: Archivo 43
A11: Auditores
A12: Avellaneda
... A95: Yolanda Romo

Sheet PARAM_ESTADO
A1: ESTADO
A2: ACTIVA
A3: BAJA
A4: AVERIADO
A5: REPARADO

Sheet PARAM_CORREOS_ELECTRONICOS
A1: CORREOS ELECTRONICOS
A2: qgil@euromadi.es

Sheet REVISIONES
A1: NUM_REVISION | B1: REVISADO | C1: EQUIPO | D1: CODIGO | E1: ESTADO | F1: PLANTA | G1: LOCALIZACION | H1: FECHA_REVISION | I1: OBSERVACIONES | J1: ENVIAR_MAIL

Sheet PARAM_DIAS_REVISION
A1: DIAS
A2: 365
A3: 180
A4: 90
